Workbook

Sheet Card Exp Settlm Computation
A1: DATE | B1: (POS Trans)Vol | C1: (POS Trans)Val | D1: (WEB Trans)Vol | E1: (WEB Trans)Val | F1: (WEB exp Settl) | G1: Total Volume | H1: Total Value | I1: Expected Settlement (Polaris)
A2: 46023 | B2: 9 | C2: ='01-01-2026'!G11 -> 358100 | D2: 0 | E2: 0 | F2: 0 | G2: =B2+D2 -> 9 | H2: =C2+E2 -> 358100 | I2: ='01-01-2026'!J11 -> 356716.48
A3: 46024 | B3: 5 | C3: ='02-01-2026'!G7 -> 41500 | D3: 0 | E3: 0 | F3: 0 | G3: =B3+D3 -> 5 | H3: =C3+E3 -> 41500 | I3: ='02-01-2026'!J7 -> 41276.938
A4: 46025 | B4: 15 | C4: ='03-01-2026'!G17 -> 127000 | D4: 0 | E4: 0 | F4: 0 | G4: =B4+D4 -> 15 | H4: =C4+E4 -> 127000 | I4: ='03-01-2026'!J17 -> 126317.37
A5: 46026 | B5: 4 | C5: ='04-01-2026'!G6 -> 25200 | D5: 0 | E5: 0 | F5: 0 | G5: =B5+D5 -> 4 | H5: =C5+E5 -> 25200 | I5: ='04-01-2026'!J6 -> 25064.55
A6: 46027 | B6: 7 | C6: ='05-01-2026'!G9 -> 23400 | D6: 0 | E6: 0 | F6: 0 | G6: =B6+D6 -> 7 | H6: =C6+E6 -> 23400 | I6: ='05-01-2026'!J9 -> 23274.225
A7: 46028 | B7: 4 | C7: ='06-01-2026'!G6 -> 28900 | D7: 0 | E7: 0 | F7: 0 | G7: =B7+D7 -> 4 | H7: =C7+E7 -> 28900 | I7: ='06-01-2026'!J6 -> 28744.662
A8: 46029 | B8: 3 | C8: ='07-01-2026'!G5 -> 19100 | D8: 0 | E8: 0 | F8: 0 | G8: =B8+D8 -> 3 | H8: =C8+E8 -> 19100 | I8: ='07-01-2026'!J5 -> 18997.338
A9: 46030 | B9: 6 | C9: ='08-01-2026'!G8 -> 34300 | D9: 0 | E9: 0 | F9: 0 | G9: =B9+D9 -> 6 | H9: =C9+E9 -> 34300 | I9: ='08-01-2026'!J8 -> 34115.637
A10: 46031 | B10: 5 | C10: ='09-01-2026'!G7 -> 30600 | D10: 0 | E10: 0 | F10: 0 | G10: =B10+D10 -> 5 | H10: =C10+E10 -> 30600 | I10: ='09-01-2026'!J7 -> 30435.525
A11: 46032 | B11: 2 | C11: ='10-01-2026'!G4 -> 15100 | D11: 0 | E11: 0 | F11: 0 | G11: =B11+D11 -> 2 | H11: =C11+E11 -> 15100 | I11: ='10-01-2026'!J4 -> 15018.837
A12: 46033 | B12: 5 | C12: ='11-01-2026'!G7 -> 26600 | D12: 0 | E12: 0 | F12: 0 | G12: =B12+D12 -> 5 | H12: =C12+E12 -> 26600 | I12: ='11-01-2026'!J7 -> 26457.025
A13: 46034 | B13: 5 | C13: ='12-01-2026'!G7 -> 33800 | D13: 1 | E13: ='12-01-2026'!G11 -> 500 | F13: ='12-01-2026'!J11 -> 491.9375 | G13: =B13+D13 -> 6 | H13: =C13+E13 -> 34300 | I13: =F13+'12-01-2026'!J7 -> 34110.262
A14: 46035 | B14: 5 | C14: ='13-01-2026'!G7 -> 62200 | D14: 0 | E14: 0 | F14: 0 | G14: =B14+D14 -> 5 | H14: =C14+E14 -> 62200 | I14: ='13-01-2026'!J7 -> 61865.675
A15: 46036 | B15: 5 | C15: ='14-01-2026'!G7 -> 94800 | D15: 0 | E15: 0 | F15: 0 | G15: =B15+D15 -> 5 | H15: =C15+E15 -> 94800 | I15: ='14-01-2026'!J7 -> 94290.45
A16: 46037 | B16: 4 | C16: ='15-01-2026'!G6 -> 32200 | D16: 0 | E16: 0 | F16: 0 | G16: =B16+D16 -> 4 | H16: =C16+E16 -> 32200 | I16: ='15-01-2026'!J6 -> 32026.925
A17: 46038 | B17: 8 | C17: ='16-01-2026'!G10 -> 117800 | D17: 0 | E17: 0 | F17: 0 | G17: =B17+D17 -> 8 | H17: =C17+E17 -> 117800 | I17: ='16-01-2026'!J10 -> 117166.82
A18: 46039 | B18: 3 | C18: ='17-01-2026'!G5 -> 23100 | D18: 0 | E18: 0 | F18: 0 | G18: =B18+D18 -> 3 | H18: =C18+E18 -> 23100 | I18: ='17-01-2026'!J5 -> 22975.838
A19: 46040 | B19: 7 | C19: ='18-01-2026'!G9 -> 30300 | D19: 0 | E19: 0 | F19: 0 | G19: =B19+D19 -> 7 | H19: =C19+E19 -> 30300 | I19: ='18-01-2026'!J9 -> 30137.138
A20: 46041 | B20: 6 | C20: ='19-01-2026'!G8 -> 28500 | D20: 0 | E20: 0 | F20: 0 | G20: =B20+D20 -> 6 | H20: =C20+E20 -> 28500 | I20: ='19-01-2026'!J8 -> 28346.812
A21: 46042 | B21: 0 | C21: 0 | D21: 0 | E21: 0 | F21: 0 | G21: =B21+D21 -> 0 | H21: =C21+E21 -> 0 | I21: =D21+F21 -> 0
A22: 46043 | B22: 5 | C22: ='21-01-2026'!G7 -> 30700 | D22: 0 | E22: 0 | F22: 0 | G22: =B22+D22 -> 5 | H22: =C22+E22 -> 30700 | I22: ='21-01-2026'!J7 -> 30534.988
A23: 46044 | B23: 1 | C23: ='22-01-2026'!G2 -> 1000 | D23: 1 | E23: ='22-01-2026'!G7 -> 500 | F23: 491.9375 | G23: =B23+D23 -> 2 | H23: =C23+E23 -> 1500 | I23: ='22-01-2026'!J2+'22-01-2026'!J7 -> 1486.5625
A24: 46045 | B24: 1 | C24: ='23-01-2026'!G2 -> 20400 | D24: 1 | E24: ='23-01-2026'!G8 -> 500 | F24: 491.9375 | G24: =B24+D24 -> 2 | H24: =C24+E24 -> 20900 | I24: ='23-01-2026'!J2+'23-01-2026'!J8 -> 20782.287
A25: 46046 | B25: 0 | C25: 0 | D25: 1 | E25: ='24-01-2026'!G3 -> 500 | F25: 491.9375 | G25: =B25+D25 -> 1 | H25: =C25+E25 -> 500 | I25: ='24-01-2026'!J3 -> 491.9375
A26: 46047 | B26: 2 | C26: ='25-01-2026'!G4 -> 15100 | D26: 0 | E26: 0 | F26: 0 | G26: =B26+D26 -> 2 | H26: =C26+E26 -> 15100 | I26: ='25-01-2026'!J4 -> 15018.837
A27: 46048 | B27: 3 | C27: ='26-01-2026'!G5 -> 11300 | D27: 0 | E27: 0 | F27: 0 | G27: =B27+D27 -> 3 | H27: =C27+E27 -> 11300 | I27: ='26-01-2026'!J5 -> 11239.263
A28: 46049 | B28: 3 | C28: ='27-01-2026'!G5 -> 14000 | D28: 0 | E28: 0 | F28: 0 | G28: =B28+D28 -> 3 | H28: =C28+E28 -> 14000 | I28: ='27-01-2026'!J5 -> 13924.75
A29: 46050 | B29: 7 | C29: ='28-01-2026'!G9 -> 38900 | D29: 0 | E29: 0 | F29: 0 | G29: =B29+D29 -> 7 | H29: =C29+E29 -> 38900 | I29: ='28-01-2026'!J9 -> 38690.912
A30: 46051 | B30: 2 | C30: ='29-01-2026'!G4 -> 15300 | D30: 0 | E30: 0 | F30: 0 | G30: =B30+D30 -> 2 | H30: =C30+E30 -> 15300 | I30: ='29-01-2026'!J4 -> 15217.762
A31: 46052 | B31: 0 | C31: 0 | D31: 0 | E31: 0 | F31: 0 | G31: =B31+D31 -> 0 | H31: =C31+E31 -> 0 | I31: =D31+F31 -> 0
A32: 46053 | B32: 4 | C32: ='31-01-2026'!G6 -> 13700 | D32: 0 | E32: 0 | F32: 0 | G32: =B32+D32 -> 4 | H32: =C32+E32 -> 13700 | I32: ='31-01-2026'!J6 -> 13626.362
A33: TOTAL | B33: =SUM(B2:B32) -> 136 | C33: =SUM(C2:C32) -> 1312900 | D33: =SUM(D2:D32) -> 4 | E33: =SUM(E2:E32) -> 2000 | F33: =SUM(F2:F32) -> 1967.75 | G33: =SUM(G2:G32) -> 140 | H33: =SUM(H2:H32) -> 1314900 | I33: =SUM(I2:I32) -> 1308352.2
C36: Pos vol | D36: =B33 -> 136
C37: Pos value | D37: =C33 -> 1312900
C38: Web vol | D38: =D33 -> 4
C39: Web value | D39: =E33 -> 2000

Sheet 01-01-2026
A1: Reference | B1: Merchant Name | C1: Payment Method | D1: Payment Source | E1: Description | F1: Currency | G1: Amount | H1: Charges | I1: Vat | J1: Settlement Due | K1: Blusalt Charge | L1: Net to CBI | M1: Stamp Duty | N1: Status | O1: Transaction Date
A2: wbxhjR2CkNJUusXGq54hb | B2: fumdam store | C2: card | D2: pos | F2: NGN | G2: 10200 | H2: =IF(G2<=200000,0.5%*G2,1000) -> 51 | I2: =7.5%*H2 -> 3.825 | J2: =G2-(H2+I2) -> 10145.175 | K2: =IF( G2<=28550,0.35%*G2,100) -> 35.7 | L2: =H2-K2 -> 15.3 | N2: successful | O2: 2026-01-01T20:42:41.381Z
A3: EqzQ4bIcelKDtet7ES87i | B3: CHICHI FASHION DESIGNER | C3: card | D3: pos | F3: NGN | G3: 5100 | H3: =IF(G3<=200000,0.5%*G3,1000) -> 25.5 | I3: =7.5%*H3 -> 1.9125 | J3: =G3-(H3+I3) -> 5072.5875 | K3: =IF( G3<=28550,0.35%*G3,100) -> 17.85 | L3: =H3-K3 -> 7.65 | N3: successful | O3: 2026-01-01T18:29:16.135Z
A4: rjgDVfG_92yNoLJZFryxB | B4: CHICHI FASHION DESIGNER | C4: card | D4: pos | F4: NGN | G4: 5200 | H4: =IF(G4<=200000,0.5%*G4,1000) -> 26 | I4: =7.5%*H4 -> 1.95 | J4: =G4-(H4+I4) -> 5172.05 | K4: =IF( G4<=28550,0.35%*G4,100) -> 18.2 | L4: =H4-K4 -> 7.8 | N4: successful | O4: 2026-01-01T18:10:06.737Z
A5: UZghQdkharpQ3F1D2AFT_ | B5: CHICHI FASHION DESIGNER | C5: card | D5: pos | F5: NGN | G5: 2100 | H5: =IF(G5<=200000,0.5%*G5,1000) -> 10.5 | I5: =7.5%*H5 -> 0.7875 | J5: =G5-(H5+I5) -> 2088.7125 | K5: =IF( G5<=28550,0.35%*G5,100) -> 7.35 | L5: =H5-K5 -> 3.15 | N5: successful | O5: 2026-01-01T16:59:20.911Z
A6: 5SSXdyzAZF9VJhEbekTZ0 | B6: CHICHI FASHION DESIGNER | C6: card | D6: pos | F6: NGN | G6: 5100 | H6: =IF(G6<=200000,0.5%*G6,1000) -> 25.5 | I6: =7.5%*H6 -> 1.9125 | J6: =G6-(H6+I6) -> 5072.5875 | K6: =IF( G6<=28550,0.35%*G6,100) -> 17.85 | L6: =H6-K6 -> 7.65 | N6: successful | O6: 2026-01-01T15:18:44.722Z
A7: 30mBviUNJxoG6UMEtpB4B | B7: CHICHI FASHION DESIGNER | C7: card | D7: pos | F7: NGN | G7: 9600 | H7: =IF(G7<=200000,0.5%*G7,1000) -> 48 | I7: =7.5%*H7 -> 3.6 | J7: =G7-(H7+I7) -> 9548.4 | K7: =IF( G7<=28550,0.35%*G7,100) -> 33.6 | L7: =H7-K7 -> 14.4 | N7: successful | O7: 2026-01-01T12:26:31.312Z
A8: xyR2Jkchm95cLn860O-zq | B8: Mr Chuks Catering Service | C8: card | D8: pos | F8: NGN | G8: 300700 | H8: =IF(G8<=200000,0.5%*G8,1000) -> 1000 | I8: =7.5%*H8 -> 75 | J8: =G8-(H8+I8) -> 299625 | K8: =IF( G8<=28550,0.35%*G8,100) -> 100 | L8: =H8-K8 -> 900 | N8: successful | O8: 2026-01-01T11:03:14.111Z
A9: IfQ_16NKOfpKTbBePN9Vn | B9: CHICHI FASHION DESIGNER | C9: card | D9: pos | F9: NGN | G9: 5100 | H9: =IF(G9<=200000,0.5%*G9,1000) -> 25.5 | I9: =7.5%*H9 -> 1.9125 | J9: =G9-(H9+I9) -> 5072.5875 | K9: =IF( G9<=28550,0.35%*G9,100) -> 17.85 | L9: =H9-K9 -> 7.65 | N9: successful | O9: 2026-01-01T08:09:18.241Z
A10: iCsZHLR9bSvItQ7pdTME4 | B10: CHICHI FASHION DESIGNER | C10: card | D10: pos | F10: NGN | G10: 15000 | H10: =IF(G10<=200000,0.5%*G10,1000) -> 75 | I10: =7.5%*H10 -> 5.625 | J10: =G10-(H10+I10) -> 14919.375 | K10: =IF( G10<=28550,0.35%*G10,100) -> 52.5 | L10: =H10-K10 -> 22.5 | N10: successful | O10: 2026-01-01T07:00:23.503Z
G11: =SUM(G2:G10) -> 358100 | H11: =SUM(H2:H10) -> 1287 | I11: =SUM(I2:I10) -> 96.525 | J11: =SUM(J2:J10) -> 356716.48 | K11: =SUM(K2:K10) -> 300.9 | L11: =SUM(L2:L10) -> 986.1

Sheet 02-01-2026
A1: Reference | B1: Merchant Name | C1: Payment Method | D1: Payment Source | E1: Description | F1: Currency | G1: Amount | H1: Charges | I1: Vat | J1: Settlement Due | K1: Blusalt Charge | L1: Net to CBI | M1: Stamp Duty | N1: Status | O1: Transaction Date
A2: EaEuI1xxLsbr1IaeF-Iq3 | B2: fumdam store | C2: card | D2: pos | F2: NGN | G2: 10200 | H2: =IF(G2<=200000,0.5%*G2,1000) -> 51 | I2: =7.5%*H2 -> 3.825 | J2: =G2-(H2+I2) -> 10145.175 | K2: =IF( G2<=28550,0.35%*G2,100) -> 35.7 | L2: =H2-K2 -> 15.3 | N2: successful | O2: 2026-01-02T21:38:11.107Z
A3: x4cADtYkqoTgchk05YG6b | B3: CHICHI FASHION DESIGNER | C3: card | D3: pos | F3: NGN | G3: 1100 | H3: =IF(G3<=200000,0.5%*G3,1000) -> 5.5 | I3: =7.5%*H3 -> 0.4125 | J3: =G3-(H3+I3) -> 1094.0875 | K3: =IF( G3<=28550,0.35%*G3,100) -> 3.85 | L3: =H3-K3 -> 1.65 | N3: successful | O3: 2026-01-02T16:09:29.016Z
A4: M3i3YcUcR4Kn4J7GpLybT | B4: CHICHI FASHION DESIGNER | C4: card | D4: pos | F4: NGN | G4: 5100 | H4: =IF(G4<=200000,0.5%*G4,1000) -> 25.5 | I4: =7.5%*H4 -> 1.9125 | J4: =G4-(H4+I4) -> 5072.5875 | K4: =IF( G4<=28550,0.35%*G4,100) -> 17.85 | L4: =H4-K4 -> 7.65 | N4: successful | O4: 2026-01-02T15:17:01.695Z
A5: eVA6WIY1EzwQzXDLss7c5 | B5: CHICHI FASHION DESIGNER | C5: card | D5: pos | F5: NGN | G5: 22000 | H5: =IF(G5<=200000,0.5%*G5,1000) -> 110 | I5: =7.5%*H5 -> 8.25 | J5: =G5-(H5+I5) -> 21881.75 | K5: =IF( G5<=28550,0.35%*G5,100) -> 77 | L5: =H5-K5 -> 33 | N5: successful | O5: 2026-01-02T10:15:41.168Z
A6: xa2tjpKzUYEd3aMcPQrds | B6: CHICHI FASHION DESIGNER | C6: card | D6: pos | F6: NGN | G6: 3100 | H6: =IF(G6<=200000,0.5%*G6,1000) -> 15.5 | I6: =7.5%*H6 -> 1.1625 | J6: =G6-(H6+I6) -> 3083.3375 | K6: =IF( G6<=28550,0.35%*G6,100) -> 10.85 | L6: =H6-K6 -> 4.65 | N6: successful | O6: 2026-01-02T09:35:02.763Z
G7: =SUM(G2:G6) -> 41500 | H7: =SUM(H2:H6) -> 207.5 | I7: =SUM(I2:I6) -> 15.5625 | J7: =SUM(J2:J6) -> 41276.938 | K7: =SUM(K2:K6) -> 145.25 | L7: =SUM(L2:L6) -> 62.25

Sheet 03-01-2026
A1: Reference | B1: Merchant Name | C1: Payment Method | D1: Payment Source | E1: Description | F1: Currency | G1: Amount | H1: Charges | I1: Vat | J1: Settlement Due | K1: Blusalt Charge | L1: Net to CBI | M1: Stamp Duty | N1: Status | O1: Transaction Date
A2: YFFySmevz0Vf6vUhm8Ws_ | B2: fumdam store | C2: card | D2: pos | F2: NGN | G2: 10100 | H2: =IF(G2<=200000,0.5%*G2,1000) -> 50.5 | I2: =7.5%*H2 -> 3.7875 | J2: =G2-(H2+I2) -> 10045.712 | K2: =IF( G2<=28550,0.35%*G2,100) -> 35.35 | L2: =H2-K2 -> 15.15 | N2: successful | O2: 2026-01-03T22:09:06.644Z
A3: wGX1WXChzHOIAqFODIhsF | B3: DON ECUS MOBILE VENTURES | C3: card | D3: pos | F3: NGN | G3: 5000 | H3: =IF(G3<=200000,0.5%*G3,1000) -> 25 | I3: =7.5%*H3 -> 1.875 | J3: =G3-(H3+I3) -> 4973.125 | K3: =IF( G3<=28550,0.35%*G3,100) -> 17.5 | L3: =H3-K3 -> 7.5 | N3: successful | O3: 2026-01-03T19:08:34.969Z
A4: AObnUgEGZsKKil3iv8reL | B4: DON ECUS MOBILE VENTURES | C4: card | D4: pos | F4: NGN | G4: 5000 | H4: =IF(G4<=200000,0.5%*G4,1000) -> 25 | I4: =7.5%*H4 -> 1.875 | J4: =G4-(H4+I4) -> 4973.125 | K4: =IF( G4<=28550,0.35%*G4,100) -> 17.5 | L4: =H4-K4 -> 7.5 | N4: successful | O4: 2026-01-03T16:50:18.585Z
A5: eSwclvFjmnJI-MXcXLEot | B5: DON ECUS MOBILE VENTURES | C5: card | D5: pos | F5: NGN | G5: 2000 | H5: =IF(G5<=200000,0.5%*G5,1000) -> 10 | I5: =7.5%*H5 -> 0.75 | J5: =G5-(H5+I5) -> 1989.25 | K5: =IF( G5<=28550,0.35%*G5,100) -> 7 | L5: =H5-K5 -> 3 | N5: successful | O5: 2026-01-03T15:02:48.774Z
A6: o9j7fSJPZuW9yOXKXxE_a | B6: DON ECUS MOBILE VENTURES | C6: card | D6: pos | F6: NGN | G6: 5000 | H6: =IF(G6<=200000,0.5%*G6,1000) -> 25 | I6: =7.5%*H6 -> 1.875 | J6: =G6-(H6+I6) -> 4973.125 | K6: =IF( G6<=28550,0.35%*G6,100) -> 17.5 | L6: =H6-K6 -> 7.5 | N6: successful | O6: 2026-01-03T13:14:46.047Z
A7: 1VhEopL2NOiEHEddRO87M | B7: DON ECUS MOBILE VENTURES | C7: card | D7: pos | F7: NGN | G7: 20000 | H7: =IF(G7<=200000,0.5%*G7,1000) -> 100 | I7: =7.5%*H7 -> 7.5 | J7: =G7-(H7+I7) -> 19892.5 | K7: =IF( G7<=28550,0.35%*G7,100) -> 70 | L7: =H7-K7 -> 30 | N7: successful | O7: 2026-01-03T13:00:11.246Z
A8: jSU_lxArdG2pSWC2HjYAS | B8: DON ECUS MOBILE VENTURES | C8: card | D8: pos | F8: NGN | G8: 7200 | H8: =IF(G8<=200000,0.5%*G8,1000) -> 36 | I8: =7.5%*H8 -> 2.7 | J8: =G8-(H8+I8) -> 7161.3 | K8: =IF( G8<=28550,0.35%*G8,100) -> 25.2 | L8: =H8-K8 -> 10.8 | N8: successful | O8: 2026-01-03T11:15:58.255Z
A9: RAIEMrGCJYdUW9dsyws1K | B9: DON ECUS MOBILE VENTURES | C9: card | D9: pos | F9: NGN | G9: 5000 | H9: =IF(G9<=200000,0.5%*G9,1000) -> 25 | I9: =7.5%*H9 -> 1.875 | J9: =G9-(H9+I9) -> 4973.125 | K9: =IF( G9<=28550,0.35%*G9,100) -> 17.5 | L9: =H9-K9 -> 7.5 | N9: successful | O9: 2026-01-03T10:33:15.866Z
A10: dv6eOPMG90gyjztGuYKHU | B10: DON ECUS MOBILE VENTURES | C10: card | D10: pos | F10: NGN | G10: 2000 | H10: =IF(G10<=200000,0.5%*G10,1000) -> 10 | I10: =7.5%*H10 -> 0.75 | J10: =G10-(H10+I10) -> 1989.25 | K10: =IF( G10<=28550,0.35%*G10,100) -> 7 | L10: =H10-K10 -> 3 | N10: successful | O10: 2026-01-03T09:51:26.462Z
A11: gFpcSW2OroFPa2wOgpk2J | B11: CHICHI FASHION DESIGNER | C11: card | D11: pos | F11: NGN | G11: 40200 | H11: =IF(G11<=200000,0.5%*G11,1000) -> 201 | I11: =7.5%*H11 -> 15.075 | J11: =G11-(H11+I11) -> 39983.925 | K11: =IF( G11<=28550,0.35%*G11,100) -> 100 | L11: =H11-K11 -> 101 | N11: successful | O11: 2026-01-03T09:49:58.212Z
A12: 3jQBWyTgpwb9TO85Wmeok | B12: CHICHI FASHION DESIGNER | C12: card | D12: pos | F12: NGN | G12: 5100 | H12: =IF(G12<=200000,0.5%*G12,1000) -> 25.5 | I12: =7.5%*H12 -> 1.9125 | J12: =G12-(H12+I12) -> 5072.5875 | K12: =IF( G12<=28550,0.35%*G12,100) -> 17.85 | L12: =H12-K12 -> 7.65 | N12: successful | O12: 2026-01-03T09:24:01.524Z
A13: Ga8VTKBnFw61B4oPjJcCB | B13: CHICHI FASHION DESIGNER | C13: card | D13: pos | F13: NGN | G13: 2100 | H13: =IF(G13<=200000,0.5%*G13,1000) -> 10.5 | I13: =7.5%*H13 -> 0.7875 | J13: =G13-(H13+I13) -> 2088.7125 | K13: =IF( G13<=28550,0.35%*G13,100) -> 7.35 | L13: =H13-K13 -> 3.15 | N13: successful | O13: 2026-01-03T09:22:17.166Z
... A16: 6rO9iLIyEycMyD4Yd5zx3 | B16: DON ECUS MOBILE VENTURES | C16: card | D16: pos | F16: NGN | G16: 3000 | H16: =IF(G16<=200000,0.5%*G16,1000) -> 15 | I16: =7.5%*H16 -> 1.125 | J16: =G16-(H16+I16) -> 2983.875 | K16: =IF( G16<=28550,0.35%*G16,100) -> 10.5 | L16: =H16-K16 -> 4.5 | N16: successful | O16: 2026-01-03T08:26:57.860Z
G17: =SUM(G2:G16) -> 127000 | H17: =SUM(H2:H16) -> 635 | I17: =SUM(I2:I16) -> 47.625 | J17: =SUM(J2:J16) -> 126317.37 | K17: =SUM(K2:K16) -> 403.8 | L17: =SUM(L2:L16) -> 231.2

Sheet 04-01-2026
A1: Reference | B1: Merchant Name | C1: Payment Method | D1: Payment Source | E1: Description | F1: Currency | G1: Amount | H1: Charges | I1: Vat | J1: Settlement Due | K1: Blusalt Charge | L1: Net to CBI | M1: Stamp Duty | N1: Status | O1: Transaction Date
A2: _h-_NzCzGw4eGeKtOH7DQ | B2: fumdam store | C2: card | D2: pos | F2: NGN | G2: 10200 | H2: =IF(G2<=200000,0.5%*G2,1000) -> 51 | I2: =7.5%*H2 -> 3.825 | J2: =G2-(H2+I2) -> 10145.175 | K2: =IF( G2<=28550,0.35%*G2,100) -> 35.7 | L2: =H2-K2 -> 15.3 | N2: successful | O2: 2026-01-04T21:07:33.688Z
A3: QrBsHYduohSDfqNTkR0CP | B3: CHICHI FASHION DESIGNER | C3: card | D3: pos | F3: NGN | G3: 5000 | H3: =IF(G3<=200000,0.5%*G3,1000) -> 25 | I3: =7.5%*H3 -> 1.875 | J3: =G3-(H3+I3) -> 4973.125 | K3: =IF( G3<=28550,0.35%*G3,100) -> 17.5 | L3: =H3-K3 -> 7.5 | N3: successful | O3: 2026-01-04T19:44:00.724Z
A4: Qk6CCGBlpDa57dxTjPGIv | B4: CHICHI FASHION DESIGNER | C4: card | D4: pos | F4: NGN | G4: 5000 | H4: =IF(G4<=200000,0.5%*G4,1000) -> 25 | I4: =7.5%*H4 -> 1.875 | J4: =G4-(H4+I4) -> 4973.125 | K4: =IF( G4<=28550,0.35%*G4,100) -> 17.5 | L4: =H4-K4 -> 7.5 | N4: successful | O4: 2026-01-04T16:53:57.005Z
A5: x_E6L0fccDlwIs_6bP6Jo | B5: CHICHI FASHION DESIGNER | C5: card | D5: pos | F5: NGN | G5: 5000 | H5: =IF(G5<=200000,0.5%*G5,1000) -> 25 | I5: =7.5%*H5 -> 1.875 | J5: =G5-(H5+I5) -> 4973.125 | K5: =IF( G5<=28550,0.35%*G5,100) -> 17.5 | L5: =H5-K5 -> 7.5 | N5: successful | O5: 2026-01-04T16:52:17.726Z
G6: =SUM(G2:G5) -> 25200 | H6: =SUM(H2:H5) -> 126 | I6: =SUM(I2:I5) -> 9.45 | J6: =SUM(J2:J5) -> 25064.55 | K6: =SUM(K2:K5) -> 88.2 | L6: =SUM(L2:L5) -> 37.8

Sheet 05-01-2026
A1: Reference | B1: Merchant Name | C1: Payment Method | D1: Payment Source | E1: Description | F1: Currency | G1: Amount | H1: Charges | I1: Vat | J1: Settlement Due | K1: Blusalt Charge | L1: Net to CBI | M1: Stamp Duty | N1: Status | O1: Transaction Date
A2: JC5n6uMXktLrO9j1qHytn | B2: fumdam store | C2: card | D2: pos | F2: NGN | G2: 10200 | H2: =IF(G2<=200000,0.5%*G2,1000) -> 51 | I2: =7.5%*H2 -> 3.825 | J2: =G2-(H2+I2) -> 10145.175 | K2: =IF( G2<=28550,0.35%*G2,100) -> 35.7 | L2: =H2-K2 -> 15.3 | N2: successful | O2: 2026-01-05T22:21:19.202Z
A3: DTwdsE2v7d-SUdRyzYqy9 | B3: CHICHI FASHION DESIGNER | C3: card | D3: pos | F3: NGN | G3: 1000 | H3: =IF(G3<=200000,0.5%*G3,1000) -> 5 | I3: =7.5%*H3 -> 0.375 | J3: =G3-(H3+I3) -> 994.625 | K3: =IF( G3<=28550,0.35%*G3,100) -> 3.5 | L3: =H3-K3 -> 1.5 | N3: successful | O3: 2026-01-05T20:55:08.815Z
A4: zTIw75k79hB8QDclPAgWY | B4: CHICHI FASHION DESIGNER | C4: card | D4: pos | F4: NGN | G4: 5100 | H4: =IF(G4<=200000,0.5%*G4,1000) -> 25.5 | I4: =7.5%*H4 -> 1.9125 | J4: =G4-(H4+I4) -> 5072.5875 | K4: =IF( G4<=28550,0.35%*G4,100) -> 17.85 | L4: =H4-K4 -> 7.65 | N4: successful | O4: 2026-01-05T18:53:21.363Z
A5: lLbYIhN3TH-sE1GUk8h-N | B5: CHICHI FASHION DESIGNER | C5: card | D5: pos | F5: NGN | G5: 1000 | H5: =IF(G5<=200000,0.5%*G5,1000) -> 5 | I5: =7.5%*H5 -> 0.375 | J5: =G5-(H5+I5) -> 994.625 | K5: =IF( G5<=28550,0.35%*G5,100) -> 3.5 | L5: =H5-K5 -> 1.5 | N5: successful | O5: 2026-01-05T12:31:00.279Z
A6: ZU9fPfJpCRwDiLHJy4nKA | B6: CHICHI FASHION DESIGNER | C6: card | D6: pos | F6: NGN | G6: 1000 | H6: =IF(G6<=200000,0.5%*G6,1000) -> 5 | I6: =7.5%*H6 -> 0.375 | J6: =G6-(H6+I6) -> 994.625 | K6: =IF( G6<=28550,0.35%*G6,100) -> 3.5 | L6: =H6-K6 -> 1.5 | N6: successful | O6: 2026-01-05T11:30:41.810Z
A7: vRdlsswx9pWfzY8zRCvEo | B7: CHICHI FASHION DESIGNER | C7: card | D7: pos | F7: NGN | G7: 2000 | H7: =IF(G7<=200000,0.5%*G7,1000) -> 10 | I7: =7.5%*H7 -> 0.75 | J7: =G7-(H7+I7) -> 1989.25 | K7: =IF( G7<=28550,0.35%*G7,100) -> 7 | L7: =H7-K7 -> 3 | N7: successful | O7: 2026-01-05T11:08:33.969Z
A8: eCJ9IuWzmxk546Whm-kCx | B8: CHICHI FASHION DESIGNER | C8: card | D8: pos | F8: NGN | G8: 3100 | H8: =IF(G8<=200000,0.5%*G8,1000) -> 15.5 | I8: =7.5%*H8 -> 1.1625 | J8: =G8-(H8+I8) -> 3083.3375 | K8: =IF( G8<=28550,0.35%*G8,100) -> 10.85 | L8: =H8-K8 -> 4.65 | N8: successful | O8: 2026-01-05T07:26:55.260Z
G9: =SUM(G2:G8) -> 23400 | H9: =SUM(H2:H8) -> 117 | I9: =SUM(I2:I8) -> 8.775 | J9: =SUM(J2:J8) -> 23274.225 | K9: =SUM(K2:K8) -> 81.9 | L9: =SUM(L2:L8) -> 35.1

Sheet 06-01-2026
A1: Reference | B1: Merchant Name | C1: Payment Method | D1: Payment Source | E1: Description | F1: Currency | G1: Amount | H1: Charges | I1: Vat | J1: Settlement Due | K1: Blusalt Charge | L1: Net to CBI | M1: Status
A2: wXVt8SQZOf7Fo1tMtnVZO | B2: fumdam store | C2: card | D2: pos | F2: NGN | G2: 15100 | H2: =IF(G2<=200000,0.5%*G2,1000) -> 75.5 | I2: =7.5%*H2 -> 5.6625 | J2: =G2-(H2+I2) -> 15018.837 | K2: =IF( G2<=28550,0.35%*G2,100) -> 52.85 | L2: =H2-K2 -> 22.65 | M2: successful | N2: 2026-01-06T21:52:15.741Z
A3: Sz-ysjaXs8EflRwRtihZI | B3: CHICHI FASHION DESIGNER | C3: card | D3: pos | F3: NGN | G3: 10000 | H3: =IF(G3<=200000,0.5%*G3,1000) -> 50 | I3: =7.5%*H3 -> 3.75 | J3: =G3-(H3+I3) -> 9946.25 | K3: =IF( G3<=28550,0.35%*G3,100) -> 35 | L3: =H3-K3 -> 15 | M3: successful | N3: 2026-01-06T18:46:30.685Z
A4: v9N1RIVU0Au4N2tkchxtn | B4: CHICHI FASHION DESIGNER | C4: card | D4: pos | F4: NGN | G4: 2100 | H4: =IF(G4<=200000,0.5%*G4,1000) -> 10.5 | I4: =7.5%*H4 -> 0.7875 | J4: =G4-(H4+I4) -> 2088.7125 | K4: =IF( G4<=28550,0.35%*G4,100) -> 7.35 | L4: =H4-K4 -> 3.15 | M4: successful | N4: 2026-01-06T15:47:20.947Z
A5: 7s-4h6riVRUlw6el-MI06 | B5: CHICHI FASHION DESIGNER | C5: card | D5: pos | F5: NGN | G5: 1700 | H5: =IF(G5<=200000,0.5%*G5,1000) -> 8.5 | I5: =7.5%*H5 -> 0.6375 | J5: =G5-(H5+I5) -> 1690.8625 | K5: =IF( G5<=28550,0.35%*G5,100) -> 5.95 | L5: =H5-K5 -> 2.55 | M5: successful | N5: 2026-01-06T07:08:51.059Z
G6: =SUM(G2:G5) -> 28900 | H6: =IF(G6<=200000,0.5%*G6,1000) -> 144.5 | I6: =7.5%*H6 -> 10.8375 | J6: =G6-(H6+I6) -> 28744.662 | K6: =SUM(K2:K5) -> 101.15 | L6: =H6-K6 -> 43.35

Sheet 07-01-2026
A1: Reference | B1: Merchant Name | C1: Payment Method | D1: Payment Source | E1: Description | F1: Currency | G1: Amount | H1: Charges | I1: Vat | J1: Settlement Due | K1: Blusalt Charge | L1: Net to CBI | M1: Stamp Duty | N1: Status | O1: Transaction Date
A2: L4JMKZ2IMpA4yFVUuf_il | B2: fumdam store | C2: card | D2: pos | F2: NGN | G2: 10100 | H2: =IF(G2<=200000,0.5%*G2,1000) -> 50.5 | I2: =7.5%*H2 -> 3.7875 | J2: =G2-(H2+I2) -> 10045.712 | K2: =IF( G2<=28550,0.35%*G2,100) -> 35.35 | L2: =H2-K2 -> 15.15 | N2: successful | O2: 2026-01-07T22:34:34.898Z
A3: zE5_gcEX915-4kcJvlpnz | B3: CHICHI FASHION DESIGNER | C3: card | D3: pos | F3: NGN | G3: 5000 | H3: =IF(G3<=200000,0.5%*G3,1000) -> 25 | I3: =7.5%*H3 -> 1.875 | J3: =G3-(H3+I3) -> 4973.125 | K3: =IF( G3<=28550,0.35%*G3,100) -> 17.5 | L3: =H3-K3 -> 7.5 | N3: successful | O3: 2026-01-07T19:03:28.273Z
A4: LEnELDFVNIeRAJChrLyWn | B4: CHICHI FASHION DESIGNER | C4: card | D4: pos | F4: NGN | G4: 4000 | H4: =IF(G4<=200000,0.5%*G4,1000) -> 20 | I4: =7.5%*H4 -> 1.5 | J4: =G4-(H4+I4) -> 3978.5 | K4: =IF( G4<=28550,0.35%*G4,100) -> 14 | L4: =H4-K4 -> 6 | N4: successful | O4: 2026-01-07T08:09:45.069Z
G5: =SUM(G2:G4) -> 19100 | H5: =SUM(H2:H4) -> 95.5 | I5: =SUM(I2:I4) -> 7.1625 | J5: =SUM(J2:J4) -> 18997.338 | K5: =SUM(K2:K4) -> 66.85 | L5: =SUM(L2:L4) -> 28.65

Sheet 08-01-2026
A1: Reference | B1: Merchant Name | C1: Payment Method | D1: Payment Source | E1: Description | F1: Currency | G1: Amount | H1: Charges | I1: Vat | J1: Settlement Due | K1: Blusalt Charge | L1: Net to CBI | M1: Stamp Duty | N1: Status | O1: Transaction Date
A2: QukRD6PF4ifq410pLYEJg | B2: fumdam store | C2: card | D2: pos | F2: NGN | G2: 15100 | H2: =IF(G2<=200000,0.5%*G2,1000) -> 75.5 | I2: =7.5%*H2 -> 5.6625 | J2: =G2-(H2+I2) -> 15018.837 | K2: =IF( G2<=28550,0.35%*G2,100) -> 52.85 | L2: =H2-K2 -> 22.65 | N2: successful | O2: 2026-01-08T22:02:11.580Z
A3: EUO0a6Ruwm2dL94jcNoa3 | B3: CHICHI FASHION DESIGNER | C3: card | D3: pos | F3: NGN | G3: 5100 | H3: =IF(G3<=200000,0.5%*G3,1000) -> 25.5 | I3: =7.5%*H3 -> 1.9125 | J3: =G3-(H3+I3) -> 5072.5875 | K3: =IF( G3<=28550,0.35%*G3,100) -> 17.85 | L3: =H3-K3 -> 7.65 | N3: successful | O3: 2026-01-08T19:51:26.074Z
A4: DWizTClAF9y1hLyWw5gZU | B4: CHICHI FASHION DESIGNER | C4: card | D4: pos | F4: NGN | G4: 10000 | H4: =IF(G4<=200000,0.5%*G4,1000) -> 50 | I4: =7.5%*H4 -> 3.75 | J4: =G4-(H4+I4) -> 9946.25 | K4: =IF( G4<=28550,0.35%*G4,100) -> 35 | L4: =H4-K4 -> 15 | N4: successful | O4: 2026-01-08T19:13:10.768Z
A5: 22N1SKeEkLsQDlRyoZCUF | B5: CHICHI FASHION DESIGNER | C5: card | D5: pos | F5: NGN | G5: 1500 | H5: =IF(G5<=200000,0.5%*G5,1000) -> 7.5 | I5: =7.5%*H5 -> 0.5625 | J5: =G5-(H5+I5) -> 1491.9375 | K5: =IF( G5<=28550,0.35%*G5,100) -> 5.25 | L5: =H5-K5 -> 2.25 | N5: successful | O5: 2026-01-08T14:03:09.378Z
A6: SJo2YnOikAQgJ79wmw65Q | B6: CHICHI FASHION DESIGNER | C6: card | D6: pos | F6: NGN | G6: 1600 | H6: =IF(G6<=200000,0.5%*G6,1000) -> 8 | I6: =7.5%*H6 -> 0.6 | J6: =G6-(H6+I6) -> 1591.4 | K6: =IF( G6<=28550,0.35%*G6,100) -> 5.6 | L6: =H6-K6 -> 2.4 | N6: successful | O6: 2026-01-08T09:26:17.260Z
A7: wT6CnrEArQOHSpEGMk5g4 | B7: CHICHI FASHION DESIGNER | C7: card | D7: pos | F7: NGN | G7: 1000 | H7: =IF(G7<=200000,0.5%*G7,1000) -> 5 | I7: =7.5%*H7 -> 0.375 | J7: =G7-(H7+I7) -> 994.625 | K7: =IF( G7<=28550,0.35%*G7,100) -> 3.5 | L7: =H7-K7 -> 1.5 | N7: successful | O7: 2026-01-08T07:25:44.538Z
G8: =SUM(G2:G7) -> 34300 | H8: =SUM(H2:H7) -> 171.5 | I8: =SUM(I2:I7) -> 12.8625 | J8: =SUM(J2:J7) -> 34115.637 | K8: =SUM(K2:K7) -> 120.05 | L8: =SUM(L2:L7) -> 51.45

Sheet 09-01-2026
A1: Reference | B1: Merchant Name | C1: Payment Method | D1: Payment Source | E1: Description | F1: Currency | G1: Amount | H1: Charges | I1: Vat | J1: Settlement Due | K1: Blusalt Charge | L1: Net to CBI | M1: Status | N1: Transaction Date
A2: jOkcjFLr8PAHXL23HeWcA | B2: fumdam store | C2: card | D2: pos | F2: NGN | G2: 10200 | H2: =IF(G2<=200000,0.5%*G2,1000) -> 51 | I2: =7.5%*H2 -> 3.825 | J2: =G2-(H2+I2) -> 10145.175 | K2: =IF( G2<=28550,0.35%*G2,100) -> 35.7 | L2: =H2-K2 -> 15.3 | M2: successful | N2: 2026-01-09T22:09:27.012Z
A3: XNq3e2DrtW_YD8eBellhK | B3: CHICHI FASHION DESIGNER | C3: card | D3: pos | F3: NGN | G3: 5100 | H3: =IF(G3<=200000,0.5%*G3,1000) -> 25.5 | I3: =7.5%*H3 -> 1.9125 | J3: =G3-(H3+I3) -> 5072.5875 | K3: =IF( G3<=28550,0.35%*G3,100) -> 17.85 | L3: =H3-K3 -> 7.65 | M3: successful | N3: 2026-01-09T20:20:21.797Z
A4: dBK1pg7-rj-iQ0acZFg12 | B4: CHICHI FASHION DESIGNER | C4: card | D4: pos | F4: NGN | G4: 4100 | H4: =IF(G4<=200000,0.5%*G4,1000) -> 20.5 | I4: =7.5%*H4 -> 1.5375 | J4: =G4-(H4+I4) -> 4077.9625 | K4: =IF( G4<=28550,0.35%*G4,100) -> 14.35 | L4: =H4-K4 -> 6.15 | M4: successful | N4: 2026-01-09T19:31:54.882Z
A5: MtBZoYGF2ymWV2BE50New | B5: CHICHI FASHION DESIGNER | C5: card | D5: pos | F5: NGN | G5: 5200 | H5: =IF(G5<=200000,0.5%*G5,1000) -> 26 | I5: =7.5%*H5 -> 1.95 | J5: =G5-(H5+I5) -> 5172.05 | K5: =IF( G5<=28550,0.35%*G5,100) -> 18.2 | L5: =H5-K5 -> 7.8 | M5: successful | N5: 2026-01-09T19:16:12.101Z
A6: 5j1hSBqxjHxJsmbgjRZ47 | B6: CHICHI FASHION DESIGNER | C6: card | D6: pos | F6: NGN | G6: 6000 | H6: =IF(G6<=200000,0.5%*G6,1000) -> 30 | I6: =7.5%*H6 -> 2.25 | J6: =G6-(H6+I6) -> 5967.75 | K6: =IF( G6<=28550,0.35%*G6,100) -> 21 | L6: =H6-K6 -> 9 | M6: successful | N6: 2026-01-09T16:35:18.679Z
G7: =SUM(G2:G6) -> 30600 | H7: =SUM(H2:H6) -> 153 | I7: =SUM(I2:I6) -> 11.475 | J7: =SUM(J2:J6) -> 30435.525 | K7: =SUM(K2:K6) -> 107.1 | L7: =SUM(L2:L6) -> 45.9

Sheet 10-01-2026
A1: Reference | B1: Merchant Name | C1: Payment Method | D1: Payment Source | E1: Description | F1: Currency | G1: Amount | H1: Charges | I1: Vat | J1: Settlement Due | K1: Blusalt Charge | L1: Net to CBI | M1: Stamp Duty | N1: Status | O1: Transaction Date
A2: znxbuhP4jtJAOON29CIVK | B2: fumdam store | C2: card | D2: pos | F2: NGN | G2: 10100 | H2: =IF(G2<=200000,0.5%*G2,1000) -> 50.5 | I2: =7.5%*H2 -> 3.7875 | J2: =G2-(H2+I2) -> 10045.712 | K2: =IF( G2<=28550,0.35%*G2,100) -> 35.35 | L2: =H2-K2 -> 15.15 | N2: successful | O2: 2026-01-10T20:30:34.314Z
A3: 1rphYGZp_vxflN_4EUMIV | B3: CHICHI FASHION DESIGNER | C3: card | D3: pos | F3: NGN | G3: 5000 | H3: =IF(G3<=200000,0.5%*G3,1000) -> 25 | I3: =7.5%*H3 -> 1.875 | J3: =G3-(H3+I3) -> 4973.125 | K3: =IF( G3<=28550,0.35%*G3,100) -> 17.5 | L3: =H3-K3 -> 7.5 | N3: successful | O3: 2026-01-10T13:59:06.453Z
G4: =SUM(G2:G3) -> 15100 | H4: =SUM(H2:H3) -> 75.5 | I4: =SUM(I2:I3) -> 5.6625 | J4: =SUM(J2:J3) -> 15018.837 | K4: =SUM(K2:K3) -> 52.85 | L4: =SUM(L2:L3) -> 22.65

Sheet 11-01-2026
A1: Reference | B1: Merchant Name | C1: Payment Method | D1: Payment Source | E1: Description | F1: Currency | G1: Amount | H1: Charges | I1: Vat | J1: Settlement Due | K1: Blusalt Charge | L1: Net to CBI | M1: Stamp Duty | N1: Status | O1: Transaction Date
A2: 4XJcT9bH2gVXHr71pHSH0 | B2: fumdam store | C2: card | D2: pos | F2: NGN | G2: 15200 | H2: =IF(G2<=200000,0.5%*G2,1000) -> 76 | I2: =7.5%*H2 -> 5.7 | J2: =G2-(H2+I2) -> 15118.3 | K2: =IF( G2<=28550,0.35%*G2,100) -> 53.2 | L2: =H2-K2 -> 22.8 | N2: successful | O2: 2026-01-11T22:08:11.768Z
A3: ZdRGnSX6o4nLTr0qLBLnV | B3: DON ECUS MOBILE VENTURES | C3: card | D3: pos | F3: NGN | G3: 2800 | H3: =IF(G3<=200000,0.5%*G3,1000) -> 14 | I3: =7.5%*H3 -> 1.05 | J3: =G3-(H3+I3) -> 2784.95 | K3: =IF( G3<=28550,0.35%*G3,100) -> 9.8 | L3: =H3-K3 -> 4.2 | N3: successful | O3: 2026-01-11T10:41:57.332Z
A4: 7EplsHinHp03LqRt6Z7rV | B4: DON ECUS MOBILE VENTURES | C4: card | D4: pos | F4: NGN | G4: 4100 | H4: =IF(G4<=200000,0.5%*G4,1000) -> 20.5 | I4: =7.5%*H4 -> 1.5375 | J4: =G4-(H4+I4) -> 4077.9625 | K4: =IF( G4<=28550,0.35%*G4,100) -> 14.35 | L4: =H4-K4 -> 6.15 | N4: successful | O4: 2026-01-11T09:32:07.323Z
A5: pN4kYaZrkSWdFJ0i5nGVv | B5: DON ECUS MOBILE VENTURES | C5: card | D5: pos | F5: NGN | G5: 1000 | H5: =IF(G5<=200000,0.5%*G5,1000) -> 5 | I5: =7.5%*H5 -> 0.375 | J5: =G5-(H5+I5) -> 994.625 | K5: =IF( G5<=28550,0.35%*G5,100) -> 3.5 | L5: =H5-K5 -> 1.5 | N5: successful | O5: 2026-01-11T09:22:14.449Z
A6: Sd-8HVA961Qfuij4oNb4J | B6: CHICHI FASHION DESIGNER | C6: card | D6: pos | F6: NGN | G6: 3500 | H6: =IF(G6<=200000,0.5%*G6,1000) -> 17.5 | I6: =7.5%*H6 -> 1.3125 | J6: =G6-(H6+I6) -> 3481.1875 | K6: =IF( G6<=28550,0.35%*G6,100) -> 12.25 | L6: =H6-K6 -> 5.25 | N6: successful | O6: 2026-01-11T06:07:34.490Z
G7: =SUM(G2:G6) -> 26600 | H7: =SUM(H2:H6) -> 133 | I7: =SUM(I2:I6) -> 9.975 | J7: =SUM(J2:J6) -> 26457.025 | K7: =SUM(K2:K6) -> 93.1 | L7: =SUM(L2:L6) -> 39.9

Sheet 12-01-2026
A1: Reference | B1: Merchant Name | C1: Payment Method | D1: Payment Source | E1: Description | F1: Currency | G1: Amount | H1: Charges | I1: Vat | J1: Settlement Due | K1: Blusalt Charge | L1: Net to CBI | M1: Stamp Duty | N1: Status | O1: Transaction Date
A2: 17XmaFCWW45SSPAHVO33- | B2: fumdam store | C2: card | D2: pos | F2: NGN | G2: 15100 | H2: =IF(G2<=200000,0.5%*G2,1000) -> 75.5 | I2: =7.5%*H2 -> 5.6625 | J2: =G2-(H2+I2) -> 15018.837 | K2: =IF( G2<=28550,0.35%*G2,100) -> 52.85 | L2: =H2-K2 -> 22.65 | N2: successful | O2: 2026-01-12T22:30:02.691Z
A3: 1llgEA2DwfGZbGKqMmi-_ | B3: CHICHI FASHION DESIGNER | C3: card | D3: pos | F3: NGN | G3: 2100 | H3: =IF(G3<=200000,0.5%*G3,1000) -> 10.5 | I3: =7.5%*H3 -> 0.7875 | J3: =G3-(H3+I3) -> 2088.7125 | K3: =IF( G3<=28550,0.35%*G3,100) -> 7.35 | L3: =H3-K3 -> 3.15 | N3: successful | O3: 2026-01-12T14:40:46.910Z
A4: isOLl5iBOwq7Gf01ViEge | B4: DON ECUS MOBILE VENTURES | C4: card | D4: pos | F4: NGN | G4: 1300 | H4: =IF(G4<=200000,0.5%*G4,1000) -> 6.5 | I4: =7.5%*H4 -> 0.4875 | J4: =G4-(H4+I4) -> 1293.0125 | K4: =IF( G4<=28550,0.35%*G4,100) -> 4.55 | L4: =H4-K4 -> 1.95 | N4: successful | O4: 2026-01-12T10:36:05.544Z
A5: iZiSMNshbHH1sQFvD06OI | B5: CHICHI FASHION DESIGNER | C5: card | D5: pos | F5: NGN | G5: 5100 | H5: =IF(G5<=200000,0.5%*G5,1000) -> 25.5 | I5: =7.5%*H5 -> 1.9125 | J5: =G5-(H5+I5) -> 5072.5875 | K5: =IF( G5<=28550,0.35%*G5,100) -> 17.85 | L5: =H5-K5 -> 7.65 | N5: successful | O5: 2026-01-12T10:03:18.716Z
A6: D-0dAfkwieOBuMQ56oqld | B6: DON ECUS MOBILE VENTURES | C6: card | D6: pos | F6: NGN | G6: 10200 | H6: =IF(G6<=200000,0.5%*G6,1000) -> 51 | I6: =7.5%*H6 -> 3.825 | J6: =G6-(H6+I6) -> 10145.175 | K6: =IF( G6<=28550,0.35%*G6,100) -> 35.7 | L6: =H6-K6 -> 15.3 | N6: successful | O6: 2026-01-12T06:54:47.117Z
G7: =SUM(G2:G6) -> 33800 | H7: =SUM(H2:H6) -> 169 | I7: =SUM(I2:I6) -> 12.675 | J7: =SUM(J2:J6) -> 33618.325 | K7: =SUM(K2:K6) -> 118.3 | L7: =SUM(L2:L6) -> 50.7
A10: Reference | B10: Merchant Name | C10: Payment Method | D10: Payment Source | E10: Description | F10: Currency | G10: Amount | H10: Charges | I10: Vat | J10: Settlement Due | K10: Blusalt Charge | L10: Net to CBI | M10: Stamp Duty | N10: Status | O10: Transaction Date
A11: TCH-5SG_HOpvN | B11: Classy | C11: card | D11: payment-link | E11: CARD: TCH-5SG_HOpvN | F11: NGN | G11: 500 | H11: =1.5%*G11 -> 7.5 | I11: =7.5%*H11 -> 0.5625 | J11: =G11-(H11+I11) -> 491.9375 | K11: =50%*H11 -> 3.75 | L11: =H11-K11 -> 3.75 | N11: successful | O11: 2026-01-12T21:30:52.298Z

Sheet 13-01-2026
A1: Reference | B1: Merchant Name | C1: Payment Method | D1: Payment Source | E1: Description | F1: Currency | G1: Amount | H1: Charges | I1: Vat | J1: Settlement Due | K1: Blusalt Charge | L1: Net to CBI | M1: Stamp Duty | N1: Status | O1: Transaction Date
A2: eM0qARIJU_5ef07utEmgc | B2: fumdam store | C2: card | D2: pos | F2: NGN | G2: 50200 | H2: =IF(G2<=200000,0.5%*G2,1000) -> 251 | I2: =7.5%*H2 -> 18.825 | J2: =G2-(H2+I2) -> 49930.175 | K2: =IF( G2<=28550,0.35%*G2,100) -> 100 | L2: =H2-K2 -> 151 | N2: successful | O2: 2026-01-13T22:00:49.616Z
A3: dSpKRVeZo6gT5vVrqRRY8 | B3: CHICHI FASHION DESIGNER | C3: card | D3: pos | F3: NGN | G3: 1900 | H3: =IF(G3<=200000,0.5%*G3,1000) -> 9.5 | I3: =7.5%*H3 -> 0.7125 | J3: =G3-(H3+I3) -> 1889.7875 | K3: =IF( G3<=28550,0.35%*G3,100) -> 6.65 | L3: =H3-K3 -> 2.85 | N3: successful | O3: 2026-01-13T19:18:40.609Z
A4: dRPO5g-0rcLAP4hz2aLMl | B4: CHICHI FASHION DESIGNER | C4: card | D4: pos | F4: NGN | G4: 2600 | H4: =IF(G4<=200000,0.5%*G4,1000) -> 13 | I4: =7.5%*H4 -> 0.975 | J4: =G4-(H4+I4) -> 2586.025 | K4: =IF( G4<=28550,0.35%*G4,100) -> 9.1 | L4: =H4-K4 -> 3.9 | N4: successful | O4: 2026-01-13T19:05:14.033Z
A5: onLeWrZ5oVaa07eUjvzDx | B5: DON ECUS MOBILE VENTURES | C5: card | D5: pos | F5: NGN | G5: 3500 | H5: =IF(G5<=200000,0.5%*G5,1000) -> 17.5 | I5: =7.5%*H5 -> 1.3125 | J5: =G5-(H5+I5) -> 3481.1875 | K5: =IF( G5<=28550,0.35%*G5,100) -> 12.25 | L5: =H5-K5 -> 5.25 | N5: successful | O5: 2026-01-13T11:45:01.962Z
A6: wpiUsubpGc2EBJAnXx64c | B6: DON ECUS MOBILE VENTURES | C6: card | D6: pos | F6: NGN | G6: 4000 | H6: =IF(G6<=200000,0.5%*G6,1000) -> 20 | I6: =7.5%*H6 -> 1.5 | J6: =G6-(H6+I6) -> 3978.5 | K6: =IF( G6<=28550,0.35%*G6,100) -> 14 | L6: =H6-K6 -> 6 | N6: successful | O6: 2026-01-13T11:31:05.723Z
G7: =SUM(G2:G6) -> 62200 | H7: =SUM(H2:H6) -> 311 | I7: =SUM(I2:I6) -> 23.325 | J7: =SUM(J2:J6) -> 61865.675 | K7: =SUM(K2:K6) -> 142 | L7: =SUM(L2:L6) -> 169

Sheet 14-01-2026
A1: Reference | B1: Merchant Name | C1: Payment Method | D1: Payment Source | E1: Description | F1: Currency | G1: Amount | H1: Charges | I1: Vat | J1: Settlement Due | K1: Blusalt Charge | L1: Net to CBI | M1: Status | N1: Transaction Date
A2: vCyOUN99UUVGALNdCEtS5 | B2: fumdam store | C2: card | D2: pos | F2: NGN | G2: 15200 | H2: =IF(G2<=200000,0.5%*G2,1000) -> 76 | I2: =7.5%*H2 -> 5.7 | J2: =G2-(H2+I2) -> 15118.3 | K2: =IF( G2<=28550,0.35%*G2,100) -> 53.2 | L2: =H2-K2 -> 22.8 | M2: successful | N2: 2026-01-14T21:17:23.820Z
A3: PXZLzqfq-HNfi9wNgPBkA | B3: CHICHI FASHION DESIGNER | C3: card | D3: pos | F3: NGN | G3: 6100 | H3: =IF(G3<=200000,0.5%*G3,1000) -> 30.5 | I3: =7.5%*H3 -> 2.2875 | J3: =G3-(H3+I3) -> 6067.2125 | K3: =IF( G3<=28550,0.35%*G3,100) -> 21.35 | L3: =H3-K3 -> 9.15 | M3: successful | N3: 2026-01-14T18:51:39.483Z
A4: 5lNwr2yS5PnWUhNWv0Mru | B4: CHICHI FASHION DESIGNER | C4: card | D4: pos | F4: NGN | G4: 60300 | H4: =IF(G4<=200000,0.5%*G4,1000) -> 301.5 | I4: =7.5%*H4 -> 22.6125 | J4: =G4-(H4+I4) -> 59975.887 | K4: =IF( G4<=28550,0.35%*G4,100) -> 100 | L4: =H4-K4 -> 201.5 | M4: successful | N4: 2026-01-14T12:50:04.090Z
A5: qyN9-m99fRYqBmJxby7Ip | B5: CHICHI FASHION DESIGNER | C5: card | D5: pos | F5: NGN | G5: 3000 | H5: =IF(G5<=200000,0.5%*G5,1000) -> 15 | I5: =7.5%*H5 -> 1.125 | J5: =G5-(H5+I5) -> 2983.875 | K5: =IF( G5<=28550,0.35%*G5,100) -> 10.5 | L5: =H5-K5 -> 4.5 | M5: successful | N5: 2026-01-14T11:45:57.582Z
A6: kKB4pwTOHsxD4RR1ASP3X | B6: CHICHI FASHION DESIGNER | C6: card | D6: pos | F6: NGN | G6: 10200 | H6: =IF(G6<=200000,0.5%*G6,1000) -> 51 | I6: =7.5%*H6 -> 3.825 | J6: =G6-(H6+I6) -> 10145.175 | K6: =IF( G6<=28550,0.35%*G6,100) -> 35.7 | L6: =H6-K6 -> 15.3 | M6: successful | N6: 2026-01-14T06:52:39.921Z
G7: =SUM(G2:G6) -> 94800 | H7: =SUM(H2:H6) -> 474 | I7: =SUM(I2:I6) -> 35.55 | J7: =SUM(J2:J6) -> 94290.45 | K7: =SUM(K2:K6) -> 220.75 | L7: =SUM(L2:L6) -> 253.25

Sheet 15-01-2026
A1: Reference | B1: Merchant Name | C1: Payment Method | D1: Payment Source | E1: Description | F1: Currency | G1: Amount | H1: Charges | I1: Vat | J1: Settlement Due | K1: Blusalt Charge | L1: Net to CBI | M1: Status | N1: Transaction Date
A2: NHn7qI0nYHwvrNAf60PZq | B2: fumdam store | C2: card | D2: pos | F2: NGN | G2: 15200 | H2: =IF(G2<=200000,0.5%*G2,1000) -> 76 | I2: =7.5%*H2 -> 5.7 | J2: =G2-(H2+I2) -> 15118.3 | K2: =IF( G2<=28550,0.35%*G2,100) -> 53.2 | L2: =H2-K2 -> 22.8 | M2: successful | N2: 2026-01-15T21:21:29.267Z
A3: kre6Ps-IMvFQyyuhptvxs | B3: CHICHI FASHION DESIGNER | C3: card | D3: pos | F3: NGN | G3: 4000 | H3: =IF(G3<=200000,0.5%*G3,1000) -> 20 | I3: =7.5%*H3 -> 1.5 | J3: =G3-(H3+I3) -> 3978.5 | K3: =IF( G3<=28550,0.35%*G3,100) -> 14 | L3: =H3-K3 -> 6 | M3: successful | N3: 2026-01-15T19:54:03.736Z
A4: a566JC8j3Tr_qNw4cfmGu | B4: CHICHI FASHION DESIGNER | C4: card | D4: pos | F4: NGN | G4: 3000 | H4: =IF(G4<=200000,0.5%*G4,1000) -> 15 | I4: =7.5%*H4 -> 1.125 | J4: =G4-(H4+I4) -> 2983.875 | K4: =IF( G4<=28550,0.35%*G4,100) -> 10.5 | L4: =H4-K4 -> 4.5 | M4: successful | N4: 2026-01-15T18:17:10.827Z
A5: IOiMNTJuDF3nxmywgfnDF | B5: CHICHI FASHION DESIGNER | C5: card | D5: pos | F5: NGN | G5: 10000 | H5: =IF(G5<=200000,0.5%*G5,1000) -> 50 | I5: =7.5%*H5 -> 3.75 | J5: =G5-(H5+I5) -> 9946.25 | K5: =IF( G5<=28550,0.35%*G5,100) -> 35 | L5: =H5-K5 -> 15 | M5: successful | N5: 2026-01-15T06:34:08.334Z
G6: =SUM(G2:G5) -> 32200 | H6: =SUM(H2:H5) -> 161 | I6: =SUM(I2:I5) -> 12.075 | J6: =SUM(J2:J5) -> 32026.925 | K6: =SUM(K2:K5) -> 112.7 | L6: =SUM(L2:L5) -> 48.3

Sheet 16-01-2026
A1: Reference | B1: Merchant Name | C1: Payment Method | D1: Payment Source | E1: Description | F1: Currency | G1: Amount | H1: Charges | I1: Vat | J1: Settlement Due | K1: Blusalt Charge | L1: Net to CBI | M1: Stamp Duty | N1: Status | O1: Transaction Date
A2: JJZ9P5rCRUxnu5gR0Ff-w | B2: fumdam store | C2: card | D2: pos | F2: NGN | G2: 15200 | H2: =IF(G2<=200000,0.5%*G2,1000) -> 76 | I2: =7.5%*H2 -> 5.7 | J2: =G2-(H2+I2) -> 15118.3 | K2: =IF( G2<=28550,0.35%*G2,100) -> 53.2 | L2: =H2-K2 -> 22.8 | N2: successful | O2: 2026-01-16T21:44:03.462Z
A3: cpVJim2qAsSXwQo-t45Pn | B3: CHICHI FASHION DESIGNER | C3: card | D3: pos | F3: NGN | G3: 4000 | H3: =IF(G3<=200000,0.5%*G3,1000) -> 20 | I3: =7.5%*H3 -> 1.5 | J3: =G3-(H3+I3) -> 3978.5 | K3: =IF( G3<=28550,0.35%*G3,100) -> 14 | L3: =H3-K3 -> 6 | N3: successful | O3: 2026-01-16T15:55:36.828Z
A4: cgJc1n_p030yOySQ9EP3O | B4: CHICHI FASHION DESIGNER | C4: card | D4: pos | F4: NGN | G4: 10000 | H4: =IF(G4<=200000,0.5%*G4,1000) -> 50 | I4: =7.5%*H4 -> 3.75 | J4: =G4-(H4+I4) -> 9946.25 | K4: =IF( G4<=28550,0.35%*G4,100) -> 35 | L4: =H4-K4 -> 15 | N4: successful | O4: 2026-01-16T15:05:18.336Z
A5: dDg7e0a2cik1Yugv-fkbj | B5: CHICHI FASHION DESIGNER | C5: card | D5: pos | F5: NGN | G5: 2000 | H5: =IF(G5<=200000,0.5%*G5,1000) -> 10 | I5: =7.5%*H5 -> 0.75 | J5: =G5-(H5+I5) -> 1989.25 | K5: =IF( G5<=28550,0.35%*G5,100) -> 7 | L5: =H5-K5 -> 3 | N5: successful | O5: 2026-01-16T13:02:08.292Z
A6: RpeS9jBqOBuU4F8JxUZ3J | B6: CHICHI FASHION DESIGNER | C6: card | D6: pos | F6: NGN | G6: 2100 | H6: =IF(G6<=200000,0.5%*G6,1000) -> 10.5 | I6: =7.5%*H6 -> 0.7875 | J6: =G6-(H6+I6) -> 2088.7125 | K6: =IF( G6<=28550,0.35%*G6,100) -> 7.35 | L6: =H6-K6 -> 3.15 | N6: successful | O6: 2026-01-16T11:55:55.945Z
A7: suBVKdDJXhrK4fJIU7BH7 | B7: CHICHI FASHION DESIGNER | C7: card | D7: pos | F7: NGN | G7: 3300 | H7: =IF(G7<=200000,0.5%*G7,1000) -> 16.5 | I7: =7.5%*H7 -> 1.2375 | J7: =G7-(H7+I7) -> 3282.2625 | K7: =IF( G7<=28550,0.35%*G7,100) -> 11.55 | L7: =H7-K7 -> 4.95 | N7: successful | O7: 2026-01-16T10:45:26.022Z
A8: Or4QfUB90rGQB7GrL_23u | B8: CHICHI FASHION DESIGNER | C8: card | D8: pos | F8: NGN | G8: 71000 | H8: =IF(G8<=200000,0.5%*G8,1000) -> 355 | I8: =7.5%*H8 -> 26.625 | J8: =G8-(H8+I8) -> 70618.375 | K8: =IF( G8<=28550,0.35%*G8,100) -> 100 | L8: =H8-K8 -> 255 | N8: successful | O8: 2026-01-16T10:37:56.382Z
A9: y5xUp3sUOOua5nFlvTDHI | B9: CHICHI FASHION DESIGNER | C9: card | D9: pos | F9: NGN | G9: 10200 | H9: =IF(G9<=200000,0.5%*G9,1000) -> 51 | I9: =7.5%*H9 -> 3.825 | J9: =G9-(H9+I9) -> 10145.175 | K9: =IF( G9<=28550,0.35%*G9,100) -> 35.7 | L9: =H9-K9 -> 15.3 | N9: successful | O9: 2026-01-16T06:57:22.796Z
G10: =SUM(G2:G9) -> 117800 | H10: =SUM(H2:H9) -> 589 | I10: =SUM(I2:I9) -> 44.175 | J10: =SUM(J2:J9) -> 117166.82 | K10: =SUM(K2:K9) -> 263.8 | L10: =SUM(L2:L9) -> 325.2

Sheet 17-01-2026
A1: Reference | B1: Merchant Name | C1: Payment Method | D1: Payment Source | E1: Description | F1: Currency | G1: Amount | H1: Charges | I1: Vat | J1: Settlement Due | K1: Blusalt Charge | L1: Net to CBI | M1: Stamp Duty | N1: Status | O1: Transaction Date
A2: cCLJsV0fjNXZ3-I0vbPnV | B2: fumdam store | C2: card | D2: pos | F2: NGN | G2: 14900 | H2: =IF(G2<=200000,0.5%*G2,1000) -> 74.5 | I2: =7.5%*H2 -> 5.5875 | J2: =G2-(H2+I2) -> 14819.913 | K2: =IF( G2<=28550,0.35%*G2,100) -> 52.15 | L2: =H2-K2 -> 22.35 | N2: successful | O2: 2026-01-17T22:38:04.203Z
A3: dM--xgn1AEjK-sx96FzPF | B3: CHICHI FASHION DESIGNER | C3: card | D3: pos | F3: NGN | G3: 3100 | H3: =IF(G3<=200000,0.5%*G3,1000) -> 15.5 | I3: =7.5%*H3 -> 1.1625 | J3: =G3-(H3+I3) -> 3083.3375 | K3: =IF( G3<=28550,0.35%*G3,100) -> 10.85 | L3: =H3-K3 -> 4.65 | N3: successful | O3: 2026-01-17T20:48:03.914Z
A4: UF77P47bG7xJUZQ1Hj0nW | B4: CHICHI FASHION DESIGNER | C4: card | D4: pos | F4: NGN | G4: 5100 | H4: =IF(G4<=200000,0.5%*G4,1000) -> 25.5 | I4: =7.5%*H4 -> 1.9125 | J4: =G4-(H4+I4) -> 5072.5875 | K4: =IF( G4<=28550,0.35%*G4,100) -> 17.85 | L4: =H4-K4 -> 7.65 | N4: successful | O4: 2026-01-17T20:04:09.070Z
G5: =SUM(G2:G4) -> 23100 | H5: =SUM(H2:H4) -> 115.5 | I5: =SUM(I2:I4) -> 8.6625 | J5: =SUM(J2:J4) -> 22975.838 | K5: =SUM(K2:K4) -> 80.85 | L5: =SUM(L2:L4) -> 34.65

Sheet 18-01-2026
A1: Reference | B1: Merchant Name | C1: Payment Method | D1: Payment Source | E1: Description | F1: Currency | G1: Amount | H1: Charges | I1: Vat | J1: Settlement Due | K1: Blusalt Charge | L1: Net to CBI | M1: Status | N1: Transaction Date
A2: pI_tPryyoJhT6rTZxMj5a | B2: CHICHI FASHION DESIGNER | C2: card | D2: pos | F2: NGN | G2: 1900 | H2: =IF(G2<=200000,0.5%*G2,1000) -> 9.5 | I2: =7.5%*H2 -> 0.7125 | J2: =G2-(H2+I2) -> 1889.7875 | K2: =IF( G2<=28550,0.35%*G2,100) -> 6.65 | L2: =H2-K2 -> 2.85 | M2: successful | N2: 2026-01-18T20:42:06.169Z
A3: 8jHGIH3y7ecvY0vfWL7dT | B3: CHICHI FASHION DESIGNER | C3: card | D3: pos | F3: NGN | G3: 2100 | H3: =IF(G3<=200000,0.5%*G3,1000) -> 10.5 | I3: =7.5%*H3 -> 0.7875 | J3: =G3-(H3+I3) -> 2088.7125 | K3: =IF( G3<=28550,0.35%*G3,100) -> 7.35 | L3: =H3-K3 -> 3.15 | M3: successful | N3: 2026-01-18T19:47:28.871Z
A4: FWkkkaCNsJLC8KWBugx7Z | B4: CHICHI FASHION DESIGNER | C4: card | D4: pos | F4: NGN | G4: 5000 | H4: =IF(G4<=200000,0.5%*G4,1000) -> 25 | I4: =7.5%*H4 -> 1.875 | J4: =G4-(H4+I4) -> 4973.125 | K4: =IF( G4<=28550,0.35%*G4,100) -> 17.5 | L4: =H4-K4 -> 7.5 | M4: successful | N4: 2026-01-18T19:29:55.358Z
A5: 7vZ7XozzpAH1CV-6QTEUg | B5: CHICHI FASHION DESIGNER | C5: card | D5: pos | F5: NGN | G5: 2100 | H5: =IF(G5<=200000,0.5%*G5,1000) -> 10.5 | I5: =7.5%*H5 -> 0.7875 | J5: =G5-(H5+I5) -> 2088.7125 | K5: =IF( G5<=28550,0.35%*G5,100) -> 7.35 | L5: =H5-K5 -> 3.15 | M5: successful | N5: 2026-01-18T17:55:50.552Z
A6: Jp1jrUYmB2iSKKYBT3xis | B6: CHICHI FASHION DESIGNER | C6: card | D6: pos | F6: NGN | G6: 5100 | H6: =IF(G6<=200000,0.5%*G6,1000) -> 25.5 | I6: =7.5%*H6 -> 1.9125 | J6: =G6-(H6+I6) -> 5072.5875 | K6: =IF( G6<=28550,0.35%*G6,100) -> 17.85 | L6: =H6-K6 -> 7.65 | M6: successful | N6: 2026-01-18T16:19:47.346Z
A7: r0d1uZXhTKopHef6I1ZNT | B7: CHICHI FASHION DESIGNER | C7: card | D7: pos | F7: NGN | G7: 2100 | H7: =IF(G7<=200000,0.5%*G7,1000) -> 10.5 | I7: =7.5%*H7 -> 0.7875 | J7: =G7-(H7+I7) -> 2088.7125 | K7: =IF( G7<=28550,0.35%*G7,100) -> 7.35 | L7: =H7-K7 -> 3.15 | M7: successful | N7: 2026-01-18T16:16:07.333Z
A8: N2I6Ib8PW34dgVmck-2FG | B8: CHICHI FASHION DESIGNER | C8: card | D8: pos | F8: NGN | G8: 12000 | H8: =IF(G8<=200000,0.5%*G8,1000) -> 60 | I8: =7.5%*H8 -> 4.5 | J8: =G8-(H8+I8) -> 11935.5 | K8: =IF( G8<=28550,0.35%*G8,100) -> 42 | L8: =H8-K8 -> 18 | M8: successful | N8: 2026-01-18T16:05:08.247Z
G9: =SUM(G2:G8) -> 30300 | H9: =SUM(H2:H8) -> 151.5 | I9: =SUM(I2:I8) -> 11.3625 | J9: =SUM(J2:J8) -> 30137.138 | K9: =SUM(K2:K8) -> 106.05 | L9: =SUM(L2:L8) -> 45.45

Sheet 19-01-2026
A1: Reference | B1: Merchant Name | C1: Payment Method | D1: Payment Source | E1: Description | F1: Currency | G1: Amount | H1: Charges | I1: Vat | J1: Settlement Due | K1: Blusalt Charge | L1: Net to CBI | M1: Stamp Duty | N1: Status | O1: Transaction Date
A2: pZ2TxJbAb_PEHIcGShhtf | B2: DON ECUS MOBILE VENTURES | C2: card | D2: pos | F2: NGN | G2: 6100 | H2: =IF(G2<=200000,0.5%*G2,1000) -> 30.5 | I2: =7.5%*H2 -> 2.2875 | J2: =G2-(H2+I2) -> 6067.2125 | K2: =IF( G2<=28550,0.35%*G2,100) -> 21.35 | L2: =H2-K2 -> 9.15 | N2: successful | O2: 2026-01-19T20:13:11.775Z
A3: 68SzBeoJrTT3pg_XZqhQR | B3: DON ECUS MOBILE VENTURES | C3: card | D3: pos | F3: NGN | G3: 5100 | H3: =IF(G3<=200000,0.5%*G3,1000) -> 25.5 | I3: =7.5%*H3 -> 1.9125 | J3: =G3-(H3+I3) -> 5072.5875 | K3: =IF( G3<=28550,0.35%*G3,100) -> 17.85 | L3: =H3-K3 -> 7.65 | N3: successful | O3: 2026-01-19T20:04:28.250Z
A4: pczLk-ywTY1Nn39bH31oT | B4: CHICHI FASHION DESIGNER | C4: card | D4: pos | F4: NGN | G4: 3100 | H4: =IF(G4<=200000,0.5%*G4,1000) -> 15.5 | I4: =7.5%*H4 -> 1.1625 | J4: =G4-(H4+I4) -> 3083.3375 | K4: =IF( G4<=28550,0.35%*G4,100) -> 10.85 | L4: =H4-K4 -> 4.65 | N4: successful | O4: 2026-01-19T19:21:28.994Z
A5: 9ZI0O3jayTntMdnCIvkAJ | B5: DON ECUS MOBILE VENTURES | C5: card | D5: pos | F5: NGN | G5: 2000 | H5: =IF(G5<=200000,0.5%*G5,1000) -> 10 | I5: =7.5%*H5 -> 0.75 | J5: =G5-(H5+I5) -> 1989.25 | K5: =IF( G5<=28550,0.35%*G5,100) -> 7 | L5: =H5-K5 -> 3 | N5: successful | O5: 2026-01-19T18:59:01.791Z
A6: 0dSoCT1xQ2LQNlNSN4mp0 | B6: DON ECUS MOBILE VENTURES | C6: card | D6: pos | F6: NGN | G6: 4000 | H6: =IF(G6<=200000,0.5%*G6,1000) -> 20 | I6: =7.5%*H6 -> 1.5 | J6: =G6-(H6+I6) -> 3978.5 | K6: =IF( G6<=28550,0.35%*G6,100) -> 14 | L6: =H6-K6 -> 6 | N6: successful | O6: 2026-01-19T08:35:48.590Z
A7: QmwnmWbcNlyH20bxfV_XT | B7: CHICHI FASHION DESIGNER | C7: card | D7: pos | F7: NGN | G7: 8200 | H7: =IF(G7<=200000,0.5%*G7,1000) -> 41 | I7: =7.5%*H7 -> 3.075 | J7: =G7-(H7+I7) -> 8155.925 | K7: =IF( G7<=28550,0.35%*G7,100) -> 28.7 | L7: =H7-K7 -> 12.3 | N7: successful | O7: 2026-01-19T07:55:03.144Z
G8: =SUM(G2:G7) -> 28500 | H8: =SUM(H2:H7) -> 142.5 | I8: =SUM(I2:I7) -> 10.6875 | J8: =SUM(J2:J7) -> 28346.812 | K8: =SUM(K2:K7) -> 99.75 | L8: =SUM(L2:L7) -> 42.75

Sheet 20-01-2026
A1: NO CARD TRANSACTION

Sheet 21-01-2026
A1: Reference | B1: Merchant Name | C1: Payment Method | D1: Payment Source | E1: Description | F1: Currency | G1: Amount | H1: Charges | I1: Vat | J1: Settlement Due | K1: Blusalt Charge | L1: Net to CBI | M1: Stamp Duty | N1: Status | O1: Transaction Date
A2: oLiLnRz6h-GZPk5GIR89W | B2: CHICHI FASHION DESIGNER | C2: card | D2: pos | F2: NGN | G2: 2100 | H2: =IF(G2<=200000,0.5%*G2,1000) -> 10.5 | I2: =7.5%*H2 -> 0.7875 | J2: =G2-(H2+I2) -> 2088.7125 | K2: =IF( G2<=28550,0.35%*G2,100) -> 7.35 | L2: =H2-K2 -> 3.15 | N2: successful | O2: 2026-01-21T19:42:44.282Z
A3: ykNua9Yerb6b5QZi0h7af | B3: DON ECUS MOBILE VENTURES | C3: card | D3: pos | F3: NGN | G3: 5000 | H3: =IF(G3<=200000,0.5%*G3,1000) -> 25 | I3: =7.5%*H3 -> 1.875 | J3: =G3-(H3+I3) -> 4973.125 | K3: =IF( G3<=28550,0.35%*G3,100) -> 17.5 | L3: =H3-K3 -> 7.5 | N3: successful | O3: 2026-01-21T12:13:01.991Z
A4: 2JlA9ot05T7G1UPe8ufdf | B4: DON ECUS MOBILE VENTURES | C4: card | D4: pos | F4: NGN | G4: 10000 | H4: =IF(G4<=200000,0.5%*G4,1000) -> 50 | I4: =7.5%*H4 -> 3.75 | J4: =G4-(H4+I4) -> 9946.25 | K4: =IF( G4<=28550,0.35%*G4,100) -> 35 | L4: =H4-K4 -> 15 | N4: successful | O4: 2026-01-21T10:01:26.130Z
A5: iScWeztTXvFi-jEA9PHiK | B5: DON ECUS MOBILE VENTURES | C5: card | D5: pos | F5: NGN | G5: 10000 | H5: =IF(G5<=200000,0.5%*G5,1000) -> 50 | I5: =7.5%*H5 -> 3.75 | J5: =G5-(H5+I5) -> 9946.25 | K5: =IF( G5<=28550,0.35%*G5,100) -> 35 | L5: =H5-K5 -> 15 | N5: successful | O5: 2026-01-21T09:36:04.955Z
A6: aHBB7zrUhZoU9-q4Dosx- | B6: CHICHI FASHION DESIGNER | C6: card | D6: pos | F6: NGN | G6: 3600 | H6: =IF(G6<=200000,0.5%*G6,1000) -> 18 | I6: =7.5%*H6 -> 1.35 | J6: =G6-(H6+I6) -> 3580.65 | K6: =IF( G6<=28550,0.35%*G6,100) -> 12.6 | L6: =H6-K6 -> 5.4 | N6: successful | O6: 2026-01-21T07:12:01.856Z
G7: =SUM(G2:G6) -> 30700 | H7: =SUM(H2:H6) -> 153.5 | I7: =SUM(I2:I6) -> 11.5125 | J7: =SUM(J2:J6) -> 30534.988 | K7: =SUM(K2:K6) -> 107.45 | L7: =SUM(L2:L6) -> 46.05

Sheet 22-01-2026
A1: Reference | B1: Merchant Name | C1: Payment Method | D1: Payment Source | E1: Description | F1: Currency | G1: Amount | H1: Charges | I1: Vat | J1: Settlement Due | K1: Blusalt Charge | L1: Net to CBI | M1: Stamp Duty | N1: Status | O1: Transaction Date
A2: tj6FtQDYTex9v7v_Hxz8r | B2: CHICHI FASHION DESIGNER | C2: card | D2: pos | F2: NGN | G2: 1000 | H2: =IF(G2<=200000,0.5%*G2,1000) -> 5 | I2: =7.5%*H2 -> 0.375 | J2: =G2-(H2+I2) -> 994.625 | K2: =IF( G2<=28550,0.35%*G2,100) -> 3.5 | L2: =H2-K2 -> 1.5 | N2: successful | O2: 2026-01-22T16:05:12.496Z
A5: WEB
A6: Reference | B6: Merchant Name | C6: Payment Method | D6: Payment Source | E6: Description | F6: Currency | G6: Amount | H6: Charges | I6: VAT | J6: Settlement Due | K6: Blusalt Charge | L6: Net to CBI | M6: Stamp Duty | N6: Status | O6: Transaction Date
A7: TCH-th2sAUCCM | B7: Moonsmile Enterprise | C7: card | D7: payment_collection | E7: CARD: TCH-th2sAUCCM | F7: NGN | G7: 500 | H7: 8.0625 | I7: 0.5625 | J7: 491.9375 | K7: =H7-L7 -> 4.3125 | L7: 3.75 | M7: 0 | N7: successful | O7: 2026-01-22T14:24:15.634Z

Sheet 23-01-2026
A1: Reference | B1: Merchant Name | C1: Payment Method | D1: Payment Source | E1: Description | F1: Currency | G1: Amount | H1: Charges | I1: Vat | J1: Settlement Due | K1: Blusalt Charge | L1: Net to CBI | M1: Stamp Duty | N1: Status | O1: Transaction Date
A2: wxaODlaRganibkWhTDkDh | B2: CHICHI FASHION DESIGNER | C2: card | D2: pos | F2: NGN | G2: 20400 | H2: =IF(G2<=200000,0.5%*G2,1000) -> 102 | I2: =7.5%*H2 -> 7.65 | J2: =G2-(H2+I2) -> 20290.35 | K2: =IF( G2<=28550,0.35%*G2,100) -> 71.4 | L2: =H2-K2 -> 30.6 | N2: successful | O2: 2026-01-23T06:08:47.096Z
A6: WEB
A7: Reference | B7: Merchant Name | C7: Payment Method | D7: Payment Source | E7: Description | F7: Currency | G7: Amount | H7: Charges | I7: VAT | J7: Settlement Due | K7: Blusalt Charge | L7: Net to CBI | M7: Stamp Duty | N7: Status | O7: Transaction Date
A8: TCH-jSlVnOgLH | B8: Moonsmile Enterprise | C8: card | D8: payment_collection | E8: CARD: TCH-jSlVnOgLH | F8: NGN | G8: 500 | H8: 8.0625 | I8: 0.5625 | J8: 491.9375 | K8: =H8-L8 -> 4.3125 | L8: 3.75 | M8: 0 | N8: successful | O8: 2026-01-23T10:31:15.811Z

Sheet 24-01-2026
A1: WEB
A2: Reference | B2: Merchant Name | C2: Payment Method | D2: Payment Source | E2: Description | F2: Currency | G2: Amount | H2: Charges | I2: VAT | J2: Settlement Due | K2: Blusalt Charge | L2: Net to CBI | M2: Stamp Duty | N2: Status | O2: Transaction Date
A3: TCH-g3LXbFxuF | B3: Classy | C3: card | D3: payment-page | E3: CARD: TCH-g3LXbFxuF | F3: NGN | G3: 500 | H3: 8.0625 | I3: 0.5625 | J3: 491.9375 | K3: =H3-L3 -> 4.3125 | L3: 3.75 | M3: 0 | N3: successful | O3: 2026-01-24T12:24:03.058Z

Sheet 25-01-2026
A1: Reference | B1: Merchant Name | C1: Payment Method | D1: Payment Source | E1: Description | F1: Currency | G1: Amount | H1: Charges | I1: Vat | J1: Settlement Due | K1: Blusalt Charge | L1: Net to CBI | M1: Stamp Duty | N1: Status | O1: Transaction Date
A2: 7ARQULHRR7jueS66JPJF_ | B2: CHICHI FASHION DESIGNER | C2: card | D2: pos | F2: NGN | G2: 10000 | H2: =IF(G2<=200000,0.5%*G2,1000) -> 50 | I2: =7.5%*H2 -> 3.75 | J2: =G2-(H2+I2) -> 9946.25 | K2: =IF( G2<=28550,0.35%*G2,100) -> 35 | L2: =H2-K2 -> 15 | N2: successful | O2: 2026-01-25T16:22:40.448Z
A3: bbOzAit9fdBGVTJifqhQm | B3: CHICHI FASHION DESIGNER | C3: card | D3: pos | F3: NGN | G3: 5100 | H3: =IF(G3<=200000,0.5%*G3,1000) -> 25.5 | I3: =7.5%*H3 -> 1.9125 | J3: =G3-(H3+I3) -> 5072.5875 | K3: =IF( G3<=28550,0.35%*G3,100) -> 17.85 | L3: =H3-K3 -> 7.65 | N3: successful | O3: 2026-01-25T16:02:44.638Z
G4: =SUM(G2:G3) -> 15100 | H4: =SUM(H2:H3) -> 75.5 | I4: =SUM(I2:I3) -> 5.6625 | J4: =SUM(J2:J3) -> 15018.837 | K4: =SUM(K2:K3) -> 52.85 | L4: =SUM(L2:L3) -> 22.65

Sheet 26-01-2026
A1: Reference | B1: Merchant Name | C1: Payment Method | D1: Payment Source | E1: Description | F1: Currency | G1: Amount | H1: Charges | I1: Vat | J1: Settlement Due | K1: Blusalt Charge | L1: Net to CBI | M1: Stamp Duty | N1: Status | O1: Transaction Date
A2: k6j5TY0YJV51fzDFwBHRT | B2: CHICHI FASHION DESIGNER | C2: card | D2: pos | F2: NGN | G2: 5200 | H2: =IF(G2<=200000,0.5%*G2,1000) -> 26 | I2: =7.5%*H2 -> 1.95 | J2: =G2-(H2+I2) -> 5172.05 | K2: =IF( G2<=28550,0.35%*G2,100) -> 18.2 | L2: =H2-K2 -> 7.8 | N2: successful | O2: 2026-01-26T10:12:56.372Z
A3: C75kpI5YcLIKra-HBayFt | B3: CHICHI FASHION DESIGNER | C3: card | D3: pos | F3: NGN | G3: 4100 | H3: =IF(G3<=200000,0.5%*G3,1000) -> 20.5 | I3: =7.5%*H3 -> 1.5375 | J3: =G3-(H3+I3) -> 4077.9625 | K3: =IF( G3<=28550,0.35%*G3,100) -> 14.35 | L3: =H3-K3 -> 6.15 | N3: successful | O3: 2026-01-26T07:13:08.421Z
A4: HadAg8r5jr855269FseDL | B4: CHICHI FASHION DESIGNER | C4: card | D4: pos | F4: NGN | G4: 2000 | H4: =IF(G4<=200000,0.5%*G4,1000) -> 10 | I4: =7.5%*H4 -> 0.75 | J4: =G4-(H4+I4) -> 1989.25 | K4: =IF( G4<=28550,0.35%*G4,100) -> 7 | L4: =H4-K4 -> 3 | N4: successful | O4: 2026-01-26T07:01:04.983Z
G5: =SUM(G2:G4) -> 11300 | H5: =SUM(H2:H4) -> 56.5 | I5: =SUM(I2:I4) -> 4.2375 | J5: =SUM(J2:J4) -> 11239.263 | K5: =SUM(K2:K4) -> 39.55 | L5: =SUM(L2:L4) -> 16.95

Sheet 27-01-2026
A1: Reference | B1: Merchant Name | C1: Payment Method | D1: Payment Source | E1: Description | F1: Currency | G1: Amount | H1: Charges | I1: Vat | J1: Settlement Due | K1: Blusalt Charge | L1: Net to CBI | M1: Stamp Duty | N1: Status | O1: Transaction Date
A2: lkcXwHCx9kcFqG-x9_Ej5 | B2: CHICHI FASHION DESIGNER | C2: card | D2: pos | F2: NGN | G2: 10000 | H2: =IF(G2<=200000,0.5%*G2,1000) -> 50 | I2: =7.5%*H2 -> 3.75 | J2: =G2-(H2+I2) -> 9946.25 | K2: =IF( G2<=28550,0.35%*G2,100) -> 35 | L2: =H2-K2 -> 15 | N2: successful | O2: 2026-01-27T20:27:32.856Z
A3: vgdr_dtsrxTxdTp5nTMEw | B3: CHICHI FASHION DESIGNER | C3: card | D3: pos | F3: NGN | G3: 1000 | H3: =IF(G3<=200000,0.5%*G3,1000) -> 5 | I3: =7.5%*H3 -> 0.375 | J3: =G3-(H3+I3) -> 994.625 | K3: =IF( G3<=28550,0.35%*G3,100) -> 3.5 | L3: =H3-K3 -> 1.5 | N3: successful | O3: 2026-01-27T20:05:26.142Z
A4: KisG3AOPAQrLlAW2dK8Mo | B4: CHICHI FASHION DESIGNER | C4: card | D4: pos | F4: NGN | G4: 3000 | H4: =IF(G4<=200000,0.5%*G4,1000) -> 15 | I4: =7.5%*H4 -> 1.125 | J4: =G4-(H4+I4) -> 2983.875 | K4: =IF( G4<=28550,0.35%*G4,100) -> 10.5 | L4: =H4-K4 -> 4.5 | N4: successful | O4: 2026-01-27T18:48:34.551Z
G5: =SUM(G2:G4) -> 14000 | H5: =SUM(H2:H4) -> 70 | I5: =SUM(I2:I4) -> 5.25 | J5: =SUM(J2:J4) -> 13924.75 | K5: =SUM(K2:K4) -> 49 | L5: =SUM(L2:L4) -> 21

Sheet 28-01-2026
A1: Reference | B1: Merchant Name | C1: Payment Method | D1: Payment Source | E1: Description | F1: Currency | G1: Amount | H1: Charges | I1: Vat | J1: Settlement Due | K1: Blusalt Charge | L1: Net to CBI | M1: Stamp Duty | N1: Status | O1: Transaction Date
A2: MvIVvAa4r_g0Fur5XwVLw | B2: CHICHI FASHION DESIGNER | C2: card | D2: pos | F2: NGN | G2: 5100 | H2: =IF(G2<=200000,0.5%*G2,1000) -> 25.5 | I2: =7.5%*H2 -> 1.9125 | J2: =G2-(H2+I2) -> 5072.5875 | K2: =IF( G2<=28550,0.35%*G2,100) -> 17.85 | L2: =H2-K2 -> 7.65 | N2: successful | O2: 2026-01-28T17:21:47.937Z
A3: ouMZS5GJuUjXVBOoRbuh7 | B3: DON ECUS MOBILE VENTURES | C3: card | D3: pos | F3: NGN | G3: 10000 | H3: =IF(G3<=200000,0.5%*G3,1000) -> 50 | I3: =7.5%*H3 -> 3.75 | J3: =G3-(H3+I3) -> 9946.25 | K3: =IF( G3<=28550,0.35%*G3,100) -> 35 | L3: =H3-K3 -> 15 | N3: successful | O3: 2026-01-28T17:13:49.183Z
A4: C_dCnK2GTMPtiG6wg2IJl | B4: DON ECUS MOBILE VENTURES | C4: card | D4: pos | F4: NGN | G4: 4600 | H4: =IF(G4<=200000,0.5%*G4,1000) -> 23 | I4: =7.5%*H4 -> 1.725 | J4: =G4-(H4+I4) -> 4575.275 | K4: =IF( G4<=28550,0.35%*G4,100) -> 16.1 | L4: =H4-K4 -> 6.9 | N4: successful | O4: 2026-01-28T16:29:15.394Z
A5: utnf0d9f9MmNIejDczW-1 | B5: CHICHI FASHION DESIGNER | C5: card | D5: pos | F5: NGN | G5: 5100 | H5: =IF(G5<=200000,0.5%*G5,1000) -> 25.5 | I5: =7.5%*H5 -> 1.9125 | J5: =G5-(H5+I5) -> 5072.5875 | K5: =IF( G5<=28550,0.35%*G5,100) -> 17.85 | L5: =H5-K5 -> 7.65 | N5: successful | O5: 2026-01-28T15:46:17.939Z
A6: #NAME? | B6: CHICHI FASHION DESIGNER | C6: card | D6: pos | F6: NGN | G6: 5000 | H6: =IF(G6<=200000,0.5%*G6,1000) -> 25 | I6: =7.5%*H6 -> 1.875 | J6: =G6-(H6+I6) -> 4973.125 | K6: =IF( G6<=28550,0.35%*G6,100) -> 17.5 | L6: =H6-K6 -> 7.5 | N6: successful | O6: 2026-01-28T10:05:31.522Z
A7: 4vzTkxPoE5IbmzyeXP9KO | B7: CHICHI FASHION DESIGNER | C7: card | D7: pos | F7: NGN | G7: 5100 | H7: =IF(G7<=200000,0.5%*G7,1000) -> 25.5 | I7: =7.5%*H7 -> 1.9125 | J7: =G7-(H7+I7) -> 5072.5875 | K7: =IF( G7<=28550,0.35%*G7,100) -> 17.85 | L7: =H7-K7 -> 7.65 | N7: successful | O7: 2026-01-28T09:45:39.773Z
A8: v6WeO8Js3Azg8yzZWq-p6 | B8: CHICHI FASHION DESIGNER | C8: card | D8: pos | F8: NGN | G8: 4000 | H8: =IF(G8<=200000,0.5%*G8,1000) -> 20 | I8: =7.5%*H8 -> 1.5 | J8: =G8-(H8+I8) -> 3978.5 | K8: =IF( G8<=28550,0.35%*G8,100) -> 14 | L8: =H8-K8 -> 6 | N8: successful | O8: 2026-01-28T05:45:52.046Z
G9: =SUM(G2:G8) -> 38900 | H9: =SUM(H2:H8) -> 194.5 | I9: =SUM(I2:I8) -> 14.5875 | J9: =SUM(J2:J8) -> 38690.912 | K9: =SUM(K2:K8) -> 136.15 | L9: =SUM(L2:L8) -> 58.35
A11: Note | B11: Data was available after two weeks

Sheet 29-01-2026
A1: Reference | B1: Merchant Name | C1: Payment Method | D1: Payment Source | E1: Description | F1: Currency | G1: Amount | H1: Charges | I1: Vat | J1: Settlement Due | K1: Blusalt Charge | L1: Net to CBI | M1: Stamp Duty | N1: Status | O1: Transaction Date
A2: e2hT3C6vC7_AICH4IFZTU | B2: CHICHI FASHION DESIGNER | C2: card | D2: pos | F2: NGN | G2: 10200 | H2: =IF(G2<=200000,0.5%*G2,1000) -> 51 | I2: =7.5%*H2 -> 3.825 | J2: =G2-(H2+I2) -> 10145.175 | K2: =IF( G2<=28550,0.35%*G2,100) -> 35.7 | L2: =H2-K2 -> 15.3 | N2: successful | O2: 2026-01-29T13:14:51.638Z
A3: kjxe32_GhEMhVM05iO-Xv | B3: CHICHI FASHION DESIGNER | C3: card | D3: pos | F3: NGN | G3: 5100 | H3: =IF(G3<=200000,0.5%*G3,1000) -> 25.5 | I3: =7.5%*H3 -> 1.9125 | J3: =G3-(H3+I3) -> 5072.5875 | K3: =IF( G3<=28550,0.35%*G3,100) -> 17.85 | L3: =H3-K3 -> 7.65 | N3: successful | O3: 2026-01-29T11:48:27.656Z
G4: =SUM(G2:G3) -> 15300 | H4: =SUM(H2:H3) -> 76.5 | I4: =SUM(I2:I3) -> 5.7375 | J4: =SUM(J2:J3) -> 15217.762 | K4: =SUM(K2:K3) -> 53.55 | L4: =SUM(L2:L3) -> 22.95
A6: Note | B6: Data was available after two weeks

Sheet 30-01-2026
A1: NO TRANSACTION

Sheet 31-01-2026
A1: Reference | B1: Merchant Name | C1: Payment Method | D1: Payment Source | E1: Description | F1: Currency | G1: Amount | H1: Charges | I1: Vat | J1: Settlement Due | K1: Blusalt Charge | L1: Net to CBI | M1: Stamp Duty | N1: Status | O1: Transaction Date
A2: 2mw3tD84x5DwupIXX_0_P | B2: DON ECUS MOBILE VENTURES | C2: card | D2: pos | F2: NGN | G2: 5100 | H2: =IF(G2<=200000,0.5%*G2,1000) -> 25.5 | I2: =7.5%*H2 -> 1.9125 | J2: =G2-(H2+I2) -> 5072.5875 | K2: =IF( G2<=28550,0.35%*G2,100) -> 17.85 | L2: =H2-K2 -> 7.65 | N2: successful | O2: 2026-01-31T13:37:55.158Z
A3: lLnjD8D6kbhrnOLAnxpJT | B3: DON ECUS MOBILE VENTURES | C3: card | D3: pos | F3: NGN | G3: 5000 | H3: =IF(G3<=200000,0.5%*G3,1000) -> 25 | I3: =7.5%*H3 -> 1.875 | J3: =G3-(H3+I3) -> 4973.125 | K3: =IF( G3<=28550,0.35%*G3,100) -> 17.5 | L3: =H3-K3 -> 7.5 | N3: successful | O3: 2026-01-31T12:16:13.203Z
